<?xml version="1.0" ?>
<!-- =================================================================================== -->
<!-- |    This document was autogenerated by xacro from jackal_base_with_ns.urdf.xacro | -->
<!-- |    EDITING THIS FILE BY HAND IS NOT RECOMMENDED                                 | -->
<!-- =================================================================================== -->
<robot name="jackal_kinova">
  <gazebo>
    <plugin filename="libgazebo_ros_control.so" name="gazebo_ros_control">
      <robotNamespace>/JK_01/</robotNamespace>
    </plugin>
  </gazebo>
  <material name="dark_grey">
    <color rgba="0.2 0.2 0.2 1.0"/>
  </material>
  <material name="light_grey">
    <color rgba="0.4 0.4 0.4 1.0"/>
  </material>
  <material name="yellow">
    <color rgba="0.8 0.8 0.0 1.0"/>
  </material>
  <material name="black">
    <color rgba="0.15 0.15 0.15 1.0"/>
  </material>
  <link name="JK_01/front_left_wheel_link">
    <visual>
      <origin rpy="1.5707963267948966 0 0" xyz="0 0 0"/>
      <geometry>
        <mesh filename="package://jackal_kinova_gazebo/meshes/jackal-wheel.stl"/>
      </geometry>
      <material name="black"/>
    </visual>
    <collision>
      <origin rpy="1.5707963267948966 0 0" xyz="0 0 0"/>
      <geometry>
        <cylinder length="0.04" radius="0.098"/>
      </geometry>
    </collision>
    <inertial>
      <origin rpy="0 0 0" xyz="0 0 0"/>
      <mass value="0.477"/>
      <inertia ixx="0.0013" ixy="0" ixz="0" iyy="0.0024" iyz="0" izz="0.0013"/>
    </inertial>
  </link>
  <gazebo reference="JK_01/front_left_wheel_link">
    <material>Gazebo/DarkGrey</material>
    <selfCollide>false</selfCollide>
    <mu1 value="0.75"/>
    <mu2 value="0.75"/>
    <kp value="10000000.0"/>
    <kd value="1"/>
    <fdir1 value="1 0 0"/>
  </gazebo>
  <joint name="JK_01/front_left_wheel" type="continuous">
    <parent link="JK_01/chassis_link"/>
    <child link="JK_01/front_left_wheel_link"/>
    <origin rpy="0 0 0" xyz="0.131 0.187795 0.0345"/>
    <axis xyz="0 1 0"/>
  </joint>
  <!-- In reality, Jackal has only two motors, one per side. However, it's more
         straightforward for Gazebo to simulate as if there's an actuator per wheel. -->
  <transmission name="JK_01/front_left_wheel_trans">
    <type>transmission_interface/SimpleTransmission</type>
    <joint name="JK_01/front_left_wheel">
      <hardwareInterface>hardware_interface/VelocityJointInterface</hardwareInterface>
    </joint>
    <actuator name="JK_01/front_left_actuator">
      <mechanicalReduction>1</mechanicalReduction>
    </actuator>
  </transmission>
  <link name="JK_01/front_right_wheel_link">
    <visual>
      <origin rpy="1.5707963267948966 0 0" xyz="0 0 0"/>
      <geometry>
        <mesh filename="package://jackal_kinova_gazebo/meshes/jackal-wheel.stl"/>
      </geometry>
      <material name="black"/>
    </visual>
    <collision>
      <origin rpy="1.5707963267948966 0 0" xyz="0 0 0"/>
      <geometry>
        <cylinder length="0.04" radius="0.098"/>
      </geometry>
    </collision>
    <inertial>
      <origin rpy="0 0 0" xyz="0 0 0"/>
      <mass value="0.477"/>
      <inertia ixx="0.0013" ixy="0" ixz="0" iyy="0.0024" iyz="0" izz="0.0013"/>
    </inertial>
  </link>
  <gazebo reference="JK_01/front_right_wheel_link">
    <material>Gazebo/DarkGrey</material>
    <selfCollide>false</selfCollide>
    <mu1 value="0.75"/>
    <mu2 value="0.75"/>
    <kp value="10000000.0"/>
    <kd value="1"/>
    <fdir1 value="1 0 0"/>
  </gazebo>
  <joint name="JK_01/front_right_wheel" type="continuous">
    <parent link="JK_01/chassis_link"/>
    <child link="JK_01/front_right_wheel_link"/>
    <origin rpy="0 0 0" xyz="0.131 -0.187795 0.0345"/>
    <axis xyz="0 1 0"/>
  </joint>
  <!-- In reality, Jackal has only two motors, one per side. However, it's more
         straightforward for Gazebo to simulate as if there's an actuator per wheel. -->
  <transmission name="JK_01/front_right_wheel_trans">
    <type>transmission_interface/SimpleTransmission</type>
    <joint name="JK_01/front_right_wheel">
      <hardwareInterface>hardware_interface/VelocityJointInterface</hardwareInterface>
    </joint>
    <actuator name="JK_01/front_right_actuator">
      <mechanicalReduction>1</mechanicalReduction>
    </actuator>
  </transmission>
  <link name="JK_01/rear_left_wheel_link">
    <visual>
      <origin rpy="1.5707963267948966 0 0" xyz="0 0 0"/>
      <geometry>
        <mesh filename="package://jackal_kinova_gazebo/meshes/jackal-wheel.stl"/>
      </geometry>
      <material name="black"/>
    </visual>
    <collision>
      <origin rpy="1.5707963267948966 0 0" xyz="0 0 0"/>
      <geometry>
        <cylinder length="0.04" radius="0.098"/>
      </geometry>
    </collision>
    <inertial>
      <origin rpy="0 0 0" xyz="0 0 0"/>
      <mass value="0.477"/>
      <inertia ixx="0.0013" ixy="0" ixz="0" iyy="0.0024" iyz="0" izz="0.0013"/>
    </inertial>
  </link>
  <gazebo reference="JK_01/rear_left_wheel_link">
    <material>Gazebo/DarkGrey</material>
    <selfCollide>false</selfCollide>
    <mu1 value="0.75"/>
    <mu2 value="0.75"/>
    <kp value="10000000.0"/>
    <kd value="1"/>
    <fdir1 value="1 0 0"/>
  </gazebo>
  <joint name="JK_01/rear_left_wheel" type="continuous">
    <parent link="JK_01/chassis_link"/>
    <child link="JK_01/rear_left_wheel_link"/>
    <origin rpy="0 0 0" xyz="-0.131 0.187795 0.0345"/>
    <axis xyz="0 1 0"/>
  </joint>
  <!-- In reality, Jackal has only two motors, one per side. However, it's more
         straightforward for Gazebo to simulate as if there's an actuator per wheel. -->
  <transmission name="JK_01/rear_left_wheel_trans">
    <type>transmission_interface/SimpleTransmission</type>
    <joint name="JK_01/rear_left_wheel">
      <hardwareInterface>hardware_interface/VelocityJointInterface</hardwareInterface>
    </joint>
    <actuator name="JK_01/rear_left_actuator">
      <mechanicalReduction>1</mechanicalReduction>
    </actuator>
  </transmission>
  <link name="JK_01/rear_right_wheel_link">
    <visual>
      <origin rpy="1.5707963267948966 0 0" xyz="0 0 0"/>
      <geometry>
        <mesh filename="package://jackal_kinova_gazebo/meshes/jackal-wheel.stl"/>
      </geometry>
      <material name="black"/>
    </visual>
    <collision>
      <origin rpy="1.5707963267948966 0 0" xyz="0 0 0"/>
      <geometry>
        <cylinder length="0.04" radius="0.098"/>
      </geometry>
    </collision>
    <inertial>
      <origin rpy="0 0 0" xyz="0 0 0"/>
      <mass value="0.477"/>
      <inertia ixx="0.0013" ixy="0" ixz="0" iyy="0.0024" iyz="0" izz="0.0013"/>
    </inertial>
  </link>
  <gazebo reference="JK_01/rear_right_wheel_link">
    <material>Gazebo/DarkGrey</material>
    <selfCollide>false</selfCollide>
    <mu1 value="0.75"/>
    <mu2 value="0.75"/>
    <kp value="10000000.0"/>
    <kd value="1"/>
    <fdir1 value="1 0 0"/>
  </gazebo>
  <joint name="JK_01/rear_right_wheel" type="continuous">
    <parent link="JK_01/chassis_link"/>
    <child link="JK_01/rear_right_wheel_link"/>
    <origin rpy="0 0 0" xyz="-0.131 -0.187795 0.0345"/>
    <axis xyz="0 1 0"/>
  </joint>
  <!-- In reality, Jackal has only two motors, one per side. However, it's more
         straightforward for Gazebo to simulate as if there's an actuator per wheel. -->
  <transmission name="JK_01/rear_right_wheel_trans">
    <type>transmission_interface/SimpleTransmission</type>
    <joint name="JK_01/rear_right_wheel">
      <hardwareInterface>hardware_interface/VelocityJointInterface</hardwareInterface>
    </joint>
    <actuator name="JK_01/rear_right_actuator">
      <mechanicalReduction>1</mechanicalReduction>
    </actuator>
  </transmission>
  <link name="JK_01/base_link"/>
  <joint name="JK_01/base_link_joint" type="fixed">
    <origin rpy="0 0 0" xyz="0 0 0"/>
    <parent link="JK_01/base_link"/>
    <child link="JK_01/chassis_link"/>
  </joint>
  <link name="JK_01/chassis_link">
    <visual>
      <origin rpy="1.5707963267948966 0 1.5707963267948966" xyz="0 0 -0.0655"/>
      <geometry>
        <mesh filename="package://jackal_kinova_gazebo/meshes/jackal-base.stl"/>
      </geometry>
      <material name="dark_grey"/>
    </visual>
    <inertial>
      <!-- Center of mass -->
      <origin rpy="0 0 0" xyz="0.012  0.002 0.067"/>
      <mass value="16.523"/>
      <!-- Moments of inertia: ( chassis without wheels ) -->
      <inertia ixx="0.3136" ixy="-0.0008" ixz="0.0164" iyy="0.3922" iyz="-0.0009" izz="0.4485"/>
    </inertial>
  </link>
  <link name="JK_01/front_fender_link">
    <visual>
      <geometry>
        <mesh filename="package://jackal_kinova_gazebo/meshes/jackal-fender.stl"/>
      </geometry>
      <material name="yellow"/>
    </visual>
    <collision name="JK_01/front_fender_collision">
      <geometry>
        <mesh filename="package://jackal_kinova_gazebo/meshes/jackal-fender.stl" scale="1.2 1.2 1.0"/>
      </geometry>
    </collision>
  </link>
  <joint name="JK_01/front_fender_joint" type="fixed">
    <origin rpy="0 0 0" xyz="0 0 0"/>
    <parent link="JK_01/chassis_link"/>
    <child link="JK_01/front_fender_link"/>
  </joint>
  <link name="JK_01/rear_fender_link">
    <visual>
      <geometry>
        <mesh filename="package://jackal_kinova_gazebo/meshes/jackal-fender.stl"/>
      </geometry>
      <material name="yellow"/>
    </visual>
    <collision name="JK_01/rear_fender_collision">
      <geometry>
        <mesh filename="package://jackal_kinova_gazebo/meshes/jackal-fender.stl" scale="1.2 1.2 1.0"/>
      </geometry>
    </collision>
  </link>
  <joint name="JK_01/rear_fender_joint" type="fixed">
    <origin rpy="0 0 3.141592653589793" xyz="0 0 0"/>
    <parent link="JK_01/chassis_link"/>
    <child link="JK_01/rear_fender_link"/>
  </joint>
  <!-- Default Internal IMU Link -->
  <link name="JK_01/imu_link">
    <inertial>
      <mass value="0.001"/>
      <origin rpy="0 0 0" xyz="0 0 0"/>
      <inertia ixx="1e-09" ixy="0.0" ixz="0.0" iyy="1e-09" iyz="0.0" izz="1e-09"/>
    </inertial>
  </link>
  <joint name="JK_01/imu_joint" type="fixed">
    <parent link="JK_01/base_link"/>
    <child link="JK_01/imu_link"/>
  </joint>
  <!-- Default NAVSAT Link -->
  <link name="JK_01/navsat_link">
    <visual>
      <geometry>
        <cylinder length="0.016" radius="0.026"/>
      </geometry>
      <origin xyz="0 0 0.008"/>
      <material name="black"/>
    </visual>
  </link>
  <joint name="JK_01/navsat_joint" type="fixed">
    <parent link="JK_01/base_link"/>
    <child link="JK_01/navsat_link"/>
    <origin xyz="-0.180 0.126 0.1815"/>
  </joint>
  <link name="JK_01/mid_mount"/>
  <joint name="JK_01/mid_mount_joint" type="fixed">
    <parent link="JK_01/chassis_link"/>
    <child link="JK_01/mid_mount"/>
    <origin xyz="0 0 0.184"/>
  </joint>
  <link name="JK_01/rear_mount"/>
  <joint name="JK_01/rear_mount_joint" type="fixed">
    <parent link="JK_01/mid_mount"/>
    <child link="JK_01/rear_mount"/>
    <origin xyz="-0.12 0 0"/>
  </joint>
  <link name="JK_01/front_mount"/>
  <joint name="JK_01/front_mount_joint" type="fixed">
    <parent link="JK_01/mid_mount"/>
    <child link="JK_01/front_mount"/>
    <origin xyz="0.12 0 0"/>
  </joint>
  <!-- Optional standard accessories, including their simulation data. The rendering
       of these into the final description is controlled by optenv variables, which
       default each one to off.-->
  <!-- <xacro:include filename="$(find jackal_kinova_gazebo)/urdf/accessories.urdf.xacro" /> -->
  <!-- This file is a placeholder which is included by default from
       jackal.urdf.xacro. If a robot is being customized and requires
       additional URDF, set the JACKAL_URDF_EXTRAS environment variable
       to the full path of the file you would like included. -->
  <!-- This file is a placeholder which is included by default from
       jackal.urdf.xacro. If a robot is being customized and requires
       additional URDF, set the JACKAL_URDF_EXTRAS environment variable
       to the full path of the file you would like included. -->
  <arg default="" name="ns"/>
  <gazebo>
    <plugin filename="libhector_gazebo_ros_imu.so" name="imu_controller">
      <robotNamespace>/JK_01/</robotNamespace>
      <updateRate>50.0</updateRate>
      <frameId>JK_01/base_link</frameId>
      <bodyName>JK_01/imu_link</bodyName>
      <topicName>imu/data</topicName>
      <accelDrift>0.005 0.005 0.005</accelDrift>
      <accelGaussianNoise>0.005 0.005 0.005</accelGaussianNoise>
      <rateDrift>0.005 0.005 0.005 </rateDrift>
      <rateGaussianNoise>0.005 0.005 0.005 </rateGaussianNoise>
      <headingDrift>0.005</headingDrift>
      <headingGaussianNoise>0.005</headingGaussianNoise>
    </plugin>
  </gazebo>
  <gazebo>
    <plugin filename="libhector_gazebo_ros_gps.so" name="gps_controller">
      <updateRate>40</updateRate>
      <robotNamespace>/JK_01/</robotNamespace>
      <bodyName>JK_01/navsat_link</bodyName>
      <frameId>JK_01/base_link</frameId>
      <topicName>navsat/fix</topicName>
      <velocityTopicName>navsat/vel</velocityTopicName>
      <referenceLatitude>49.9</referenceLatitude>
      <referenceLongitude>8.9</referenceLongitude>
      <referenceHeading>0</referenceHeading>
      <referenceAltitude>0</referenceAltitude>
      <drift>0.0001 0.0001 0.0001</drift>
    </plugin>
  </gazebo>
  <gazebo>
    <plugin filename="libgazebo_ros_p3d.so" name="p3d_base_controller">
      <robotNamespace>/JK_01/</robotNamespace>
      <alwaysOn>true</alwaysOn>
      <updateRate>50.0</updateRate>
      <bodyName>JK_01/base_link</bodyName>
      <topicName>base_pose_ground_truth</topicName>
      <gaussianNoise>0.01</gaussianNoise>
      <frameName>map</frameName>
      <xyzOffsets>0 0 0</xyzOffsets>
      <rpyOffsets>0 0 0</rpyOffsets>
    </plugin>
  </gazebo>
  <gazebo reference="JK_01/base_link">
    <turnGravityOff>false</turnGravityOff>
  </gazebo>
  <gazebo reference="JK_01/chassis_link">
    <material>Gazebo/DarkGrey</material>
    <turnGravityOff>false</turnGravityOff>
  </gazebo>
  <gazebo reference="JK_01/imu_link">
    <turnGravityOff>false</turnGravityOff>
  </gazebo>
  <gazebo reference="JK_01/navsat_link">
    <material>Gazebo/DarkGrey</material>
    <turnGravityOff>false</turnGravityOff>
  </gazebo>
  <gazebo reference="JK_01/front_fender_link">
    <material>Gazebo/Yellow</material>
    <turnGravityOff>false</turnGravityOff>
  </gazebo>
  <gazebo reference="JK_01/rear_fender_link">
    <material>Gazebo/Yellow</material>
    <turnGravityOff>false</turnGravityOff>
  </gazebo>
  <gazebo reference="JK_01/rear_fender_link">
    <!-- Virtual Contact Sensor -->
    <sensor name="JK_01/rear_fender_contact_sensor" type="contact">
      <alwaysOn>true</alwaysOn>
      <updateRate>10.0</updateRate>
      <contact>
        <collision>JK_01/base_link_fixed_joint_lump__JK_01/rear_fender_collision_collision_3</collision>
      </contact>
      <plugin filename="libgazebo_ros_bumper.so" name="contact_plugin_1">
        <bumperTopicName>base_collision_1</bumperTopicName>
        <frameName>JK_01/rear_fender_link</frameName>
      </plugin>
    </sensor>
  </gazebo>
  <gazebo reference="JK_01/front_fender_link">
    <!-- Virtual Contact Sensor -->
    <sensor name="JK_01/front_fender_contact_sensor" type="contact">
      <alwaysOn>true</alwaysOn>
      <updateRate>10.0</updateRate>
      <contact>
        <collision>JK_01/base_link_fixed_joint_lump__JK_01/front_fender_collision_collision_2</collision>
      </contact>
      <plugin filename="libgazebo_ros_bumper.so" name="contact_plugin_2">
        <bumperTopicName>base_collision_2</bumperTopicName>
        <frameName>JK_01/front_fender_link</frameName>
      </plugin>
    </sensor>
  </gazebo>
  <!-- lidar, base_camera mount -->
  <link name="JK_01/top_structure">
    <visual>
      <origin rpy="1.5707963267948966 0 -1.5707963267948966" xyz="0 0 0"/>
      <geometry>
        <mesh filename="package://jackal_kinova_gazebo/meshes/top_structure_roas.STL"/>
      </geometry>
      <material name="silver">
        <color rgba="0.75 0.75 0.75 1"/>
      </material>
    </visual>
  </link>
  <joint name="JK_01/top_structure_joint" type="fixed">
    <parent link="JK_01/base_link"/>
    <child link="JK_01/top_structure"/>
    <origin rpy="0 0 0" xyz="0 0 -0.065"/>
  </joint>
  <!-- camera body, with origin at bottom screw mount -->
  <joint name="JK_01/base_camera_joint" type="fixed">
    <origin rpy="0 0 0" xyz="0.196 0 0.256"/>
    <parent link="JK_01/base_link"/>
    <child link="JK_01/base_camera_bottom_screw_frame"/>
  </joint>
  <link name="JK_01/base_camera_bottom_screw_frame"/>
  <joint name="JK_01/base_camera_link_joint" type="fixed">
    <origin rpy="0 0 0" xyz="0.010600000000000002 0.0175 0.0125"/>
    <parent link="JK_01/base_camera_bottom_screw_frame"/>
    <child link="JK_01/base_camera_link"/>
  </joint>
  <link name="JK_01/base_camera_link">
    <visual>
      <origin rpy="1.5707963267948966 0 1.5707963267948966" xyz="0.0043 -0.0175 0"/>
      <geometry>
        <mesh filename="package://jackal_kinova_gazebo/meshes/include/d435.dae"/>
      </geometry>
    </visual>
    <inertial>
      <mass value="0.564"/>
      <origin xyz="0 0 0"/>
      <inertia ixx="0.003881243" ixy="0.0" ixz="0.0" iyy="0.000498940" iyz="0.0" izz="0.003879257"/>
    </inertial>
    <collision>
      <origin rpy="0 0 0" xyz="0 -0.0175 0"/>
      <geometry>
        <box size="0.02505 0.09 0.025"/>
      </geometry>
    </collision>
  </link>
  <!-- camera depth joints and links -->
  <joint name="JK_01/base_camera_depth_joint" type="fixed">
    <origin rpy="0 0 0" xyz="0 0 0"/>
    <parent link="JK_01/base_camera_link"/>
    <child link="JK_01/base_camera_depth_frame"/>
  </joint>
  <link name="JK_01/base_camera_depth_frame"/>
  <joint name="JK_01/base_camera_depth_optical_joint" type="fixed">
    <origin rpy="-1.5707963267948966 0 -1.5707963267948966" xyz="0 0 0"/>
    <parent link="JK_01/base_camera_depth_frame"/>
    <child link="JK_01/base_camera_depth_optical_frame"/>
  </joint>
  <link name="JK_01/base_camera_depth_optical_frame"/>
  <!-- camera left IR joints and links -->
  <joint name="JK_01/base_camera_infra1_joint" type="fixed">
    <origin rpy="0 0 0" xyz="0 0.0 0"/>
    <parent link="JK_01/base_camera_link"/>
    <child link="JK_01/base_camera_infra1_frame"/>
  </joint>
  <link name="JK_01/base_camera_infra1_frame"/>
  <joint name="JK_01/base_camera_infra1_optical_joint" type="fixed">
    <origin rpy="-1.5707963267948966 0 -1.5707963267948966" xyz="0 0 0"/>
    <parent link="JK_01/base_camera_infra1_frame"/>
    <child link="JK_01/base_camera_infra1_optical_frame"/>
  </joint>
  <link name="JK_01/base_camera_infra1_optical_frame"/>
  <!-- camera right IR joints and links -->
  <joint name="JK_01/base_camera_infra2_joint" type="fixed">
    <origin rpy="0 0 0" xyz="0 -0.05 0"/>
    <parent link="JK_01/base_camera_link"/>
    <child link="JK_01/base_camera_infra2_frame"/>
  </joint>
  <link name="JK_01/base_camera_infra2_frame"/>
  <joint name="JK_01/base_camera_infra2_optical_joint" type="fixed">
    <origin rpy="-1.5707963267948966 0 -1.5707963267948966" xyz="0 0 0"/>
    <parent link="JK_01/base_camera_infra2_frame"/>
    <child link="JK_01/base_camera_infra2_optical_frame"/>
  </joint>
  <link name="JK_01/base_camera_infra2_optical_frame"/>
  <!-- camera color joints and links -->
  <joint name="JK_01/base_camera_color_joint" type="fixed">
    <origin rpy="0 0 0" xyz="0 0.015 0"/>
    <parent link="JK_01/base_camera_link"/>
    <child link="JK_01/base_camera_color_frame"/>
  </joint>
  <link name="JK_01/base_camera_color_frame"/>
  <joint name="JK_01/base_camera_color_optical_joint" type="fixed">
    <origin rpy="-1.5707963267948966 0 -1.5707963267948966" xyz="0 0 0"/>
    <parent link="JK_01/base_camera_color_frame"/>
    <child link="JK_01/base_camera_color_optical_frame"/>
  </joint>
  <link name="JK_01/base_camera_color_optical_frame"/>
  <link name="JK_01/base_camera_gazebo"/>
  <joint name="JK_01/base_camera_gazebo_joint" type="fixed">
    <parent link="JK_01/base_camera_link"/>
    <child link="JK_01/base_camera_gazebo"/>
    <origin rpy="0 0 0" xyz="0.0 0 0"/>
  </joint>
  <gazebo reference="JK_01/base_camera_link">
    <sensor name="JK_01/base_cameracolor" type="camera">
      <camera name="base_camera">
        <horizontal_fov>1.211259</horizontal_fov>
        <image>
          <width>640</width>
          <height>480</height>
          <format>RGB_INT8</format>
        </image>
        <clip>
          <near>0.1</near>
          <far>100</far>
        </clip>
        <noise>
          <type>gaussian</type>
          <mean>0.0</mean>
          <stddev>0.007</stddev>
        </noise>
      </camera>
      <always_on>0</always_on>
      <update_rate>30</update_rate>
      <visualize>0</visualize>
    </sensor>
    <turnGravityOff>true</turnGravityOff>
    <always_on>false</always_on>
    <visualize>false</visualize>
    <sensor name="JK_01/base_camera_gazebo_depth" type="depth">
      <update_rate>30</update_rate>
      <camera>
        <!-- 75x65 degree FOV for the depth sensor -->
        <horizontal_fov>1.5184351666666667</horizontal_fov>
        <vertical_fov>1.0122901111111111</vertical_fov>
        <image>
          <width>640</width>
          <height>480</height>
          <format>RGB_INT8</format>
        </image>
        <clip>
          <!-- give the color sensor a maximum range of 50m so that the simulation renders nicely -->
          <near>0.01</near>
          <far>50.0</far>
        </clip>
      </camera>
      <plugin filename="libgazebo_ros_openni_kinect.so" name="kinect_controller">
        <baseline>0.2</baseline>
        <alwaysOn>false</alwaysOn>
        <updateRate>30</updateRate>
        <cameraName>base_camera</cameraName>
        <imageTopicName>color/image_raw</imageTopicName>
        <cameraInfoTopicName>color/camera_info</cameraInfoTopicName>
        <depthImageTopicName>depth/image_raw</depthImageTopicName>
        <depthImageInfoTopicName>depth/camera_info</depthImageInfoTopicName>
        <pointCloudTopicName>depth/color/points</pointCloudTopicName>
        <frameName>JK_01/base_camera_depth_optical_frame</frameName>
        <pointCloudCutoff>0.105</pointCloudCutoff>
        <pointCloudCutoffMax>8.0</pointCloudCutoffMax>
        <distortionK1>0.00000001</distortionK1>
        <distortionK2>0.00000001</distortionK2>
        <distortionK3>0.00000001</distortionK3>
        <distortionT1>0.00000001</distortionT1>
        <distortionT2>0.00000001</distortionT2>
        <CxPrime>0</CxPrime>
        <Cx>0</Cx>
        <Cy>0</Cy>
        <focalLength>0</focalLength>
        <hackBaseline>0</hackBaseline>
      </plugin>
    </sensor>
  </gazebo>
  <joint name="JK_01/laser_base_joint" type="fixed">
    <origin rpy="0 0 0" xyz="0.145 0 0.284"/>
    <parent link="JK_01/base_link"/>
    <child link="JK_01/laser_base_link"/>
  </joint>
  <link name="JK_01/laser_base_link">
    <inertial>
      <mass value="0.15"/>
      <origin rpy="3.1415926 0 0" xyz="0 0 -0.026"/>
      <inertia ixx="0.000123012450795" ixy="0.0" ixz="0.0" iyy="0.000123012450795" iyz="0.0" izz="8.9999964e-05"/>
    </inertial>
  </link>
  <joint name="JK_01/laser_joint" type="fixed">
    <origin rpy="0 0 0" xyz="0 0 -0.06246"/>
    <parent link="JK_01/laser_base_link"/>
    <child link="JK_01/laser_link"/>
  </joint>
  <link name="JK_01/laser_link">
    </link>
  <gazebo reference="JK_01/laser_link">
    <material value="Gazebo/Blue"/>
    <sensor name="JK_01/laser" type="ray">
      <always_on>true</always_on>
      <update_rate>15.0</update_rate>
      <pose>0 0 0 0 0 0</pose>
      <visualize>false</visualize>
      <ray>
        <scan>
          <horizontal>
            <samples>811</samples>
            <resolution>1</resolution>
            <min_angle>-2.35619449019</min_angle>
            <max_angle>2.35619449019</max_angle>
          </horizontal>
        </scan>
        <range>
          <min>0.05</min>
          <max>25.0</max>
          <resolution>0.01</resolution>
        </range>
        <noise>
          <type>gaussian</type>
          <mean>0.0</mean>
          <stddev>0.01</stddev>
        </noise>
      </ray>
      <plugin filename="libgazebo_ros_laser.so" name="gazebo_ros_laser_controller">
        <gaussianNoise>0.005</gaussianNoise>
        <alwaysOn>true</alwaysOn>
        <updateRate>15.0</updateRate>
        <topicName>scan</topicName>
        <frameName>JK_01/laser_link</frameName>
      </plugin>
    </sensor>
  </gazebo>
</robot>
