<sdf version='1.7'>
  <model name='jackal_kinova'>
    <link name='JK_01/base_link'>
      <inertial>
        <pose>0.019524 0.00249 0.075251 0 -0 0</pose>
        <mass>17.238</mass>
        <inertia>
          <ixx>0.344939</ixx>
          <ixy>-0.00239782</ixy>
          <ixz>-0.00845669</ixz>
          <iyy>0.443061</iyy>
          <iyz>-0.00253471</iyz>
          <izz>0.475637</izz>
        </inertia>
      </inertial>
      <collision name='JK_01/base_link_fixed_joint_lump__JK_01/base_camera_link_collision'>
        <pose>0.2066 0 0.2685 0 -0 0</pose>
        <geometry>
          <box>
            <size>0.02505 0.09 0.025</size>
          </box>
        </geometry>
        <surface>
          <contact>
            <ode/>
          </contact>
          <friction>
            <ode/>
          </friction>
        </surface>
      </collision>
      <collision name='JK_01/base_link_fixed_joint_lump__JK_01/front_fender_collision_collision_1'>
        <pose>0 0 0 0 -0 0</pose>
        <geometry>
          <mesh>
            <scale>1.2 1.2 1</scale>
            <uri>model://jackal_kinova_gazebo/meshes/jackal-fender.stl</uri>
          </mesh>
        </geometry>
      </collision>
      <collision name='JK_01/base_link_fixed_joint_lump__JK_01/rear_fender_collision_collision_2'>
        <pose>0 0 0 0 -0 3.14159</pose>
        <geometry>
          <mesh>
            <scale>1.2 1.2 1</scale>
            <uri>model://jackal_kinova_gazebo/meshes/jackal-fender.stl</uri>
          </mesh>
        </geometry>
      </collision>
      <visual name='JK_01/base_link_fixed_joint_lump__JK_01/base_camera_link_visual'>
        <pose>0.2109 0 0.2685 1.5708 -0 1.5708</pose>
        <geometry>
          <mesh>
            <scale>1 1 1</scale>
            <uri>model://jackal_kinova_gazebo/meshes/include/d435.dae</uri>
          </mesh>
        </geometry>
      </visual>
      <visual name='JK_01/base_link_fixed_joint_lump__JK_01/chassis_link_visual_1'>
        <pose>0 0 -0.0655 1.5708 -0 1.5708</pose>
        <geometry>
          <mesh>
            <scale>1 1 1</scale>
            <uri>model://jackal_kinova_gazebo/meshes/jackal-base.stl</uri>
          </mesh>
        </geometry>
        <material>
          <script>
            <name>Gazebo/DarkGrey</name>
            <uri>file://media/materials/scripts/gazebo.material</uri>
          </script>
        </material>
      </visual>
      <visual name='JK_01/base_link_fixed_joint_lump__JK_01/front_fender_link_visual_2'>
        <pose>0 0 0 0 -0 0</pose>
        <geometry>
          <mesh>
            <scale>1 1 1</scale>
            <uri>model://jackal_kinova_gazebo/meshes/jackal-fender.stl</uri>
          </mesh>
        </geometry>
        <material>
          <script>
            <name>Gazebo/Yellow</name>
            <uri>file://media/materials/scripts/gazebo.material</uri>
          </script>
        </material>
      </visual>
      <visual name='JK_01/base_link_fixed_joint_lump__JK_01/rear_fender_link_visual_3'>
        <pose>0 0 0 0 -0 3.14159</pose>
        <geometry>
          <mesh>
            <scale>1 1 1</scale>
            <uri>model://jackal_kinova_gazebo/meshes/jackal-fender.stl</uri>
          </mesh>
        </geometry>
        <material>
          <script>
            <name>Gazebo/Yellow</name>
            <uri>file://media/materials/scripts/gazebo.material</uri>
          </script>
        </material>
      </visual>
      <visual name='JK_01/base_link_fixed_joint_lump__JK_01/navsat_link_visual_4'>
        <pose>-0.18 0.126 0.1895 0 -0 0</pose>
        <geometry>
          <cylinder>
            <length>0.016</length>
            <radius>0.026</radius>
          </cylinder>
        </geometry>
        <material>
          <script>
            <name>Gazebo/DarkGrey</name>
            <uri>file://media/materials/scripts/gazebo.material</uri>
          </script>
        </material>
      </visual>
      <visual name='JK_01/base_link_fixed_joint_lump__JK_01/top_structure_visual_5'>
        <pose>0 0 -0.065 1.5708 0 -1.5708</pose>
        <geometry>
          <mesh>
            <scale>1 1 1</scale>
            <uri>model://jackal_kinova_gazebo/meshes/top_structure_roas.STL</uri>
          </mesh>
        </geometry>
      </visual>
      <sensor name='JK_01/base_cameracolor' type='camera'>
        <camera name='base_camera'>
          <horizontal_fov>1.21126</horizontal_fov>
          <image>
            <width>640</width>
            <height>480</height>
            <format>RGB_INT8</format>
          </image>
          <clip>
            <near>0.1</near>
            <far>100</far>
          </clip>
          <noise>
            <type>gaussian</type>
            <mean>0</mean>
            <stddev>0.007</stddev>
          </noise>
        </camera>
        <always_on>0</always_on>
        <update_rate>30</update_rate>
        <visualize>0</visualize>
        <pose>0.2066 0.0175 0.2685 0 -0 0</pose>
      </sensor>
      <sensor name='JK_01/base_camera_gazebo_depth' type='depth'>
        <update_rate>30</update_rate>
        <camera>
          <horizontal_fov>1.51844</horizontal_fov>
          <image>
            <width>640</width>
            <height>480</height>
            <format>RGB_INT8</format>
          </image>
          <clip>
            <near>0.01</near>
            <far>50</far>
          </clip>
          <vertical_fov>1.0122901111111111</vertical_fov>
        </camera>
        <plugin name='kinect_controller' filename='libgazebo_ros_openni_kinect.so'>
          <baseline>0.2</baseline>
          <alwaysOn>0</alwaysOn>
          <updateRate>30</updateRate>
          <cameraName>base_camera</cameraName>
          <imageTopicName>color/image_raw</imageTopicName>
          <cameraInfoTopicName>color/camera_info</cameraInfoTopicName>
          <depthImageTopicName>depth/image_raw</depthImageTopicName>
          <depthImageInfoTopicName>depth/camera_info</depthImageInfoTopicName>
          <pointCloudTopicName>depth/color/points</pointCloudTopicName>
          <frameName>JK_01/base_camera_depth_optical_frame</frameName>
          <pointCloudCutoff>0.105</pointCloudCutoff>
          <pointCloudCutoffMax>8.0</pointCloudCutoffMax>
          <distortionK1>0.00000001</distortionK1>
          <distortionK2>0.00000001</distortionK2>
          <distortionK3>0.00000001</distortionK3>
          <distortionT1>0.00000001</distortionT1>
          <distortionT2>0.00000001</distortionT2>
          <CxPrime>0</CxPrime>
          <Cx>0</Cx>
          <Cy>0</Cy>
          <focalLength>0</focalLength>
          <hackBaseline>0</hackBaseline>
        </plugin>
        <pose>0.2066 0.0175 0.2685 0 -0 0</pose>
      </sensor>
      <sensor name='JK_01/front_fender_contact_sensor' type='contact'>
        <contact>
          <collision>JK_01/base_link_fixed_joint_lump__JK_01/front_fender_collision_collision_2</collision>
          <topic>__default_topic__</topic>
        </contact>
        <plugin name='contact_plugin_2' filename='libgazebo_ros_bumper.so'>
          <bumperTopicName>base_collision_2</bumperTopicName>
          <frameName>JK_01/front_fender_link</frameName>
        </plugin>
        <pose>0 0 0 0 -0 0</pose>
        <alwaysOn>1</alwaysOn>
        <updateRate>10.0</updateRate>
      </sensor>
      <sensor name='JK_01/rear_fender_contact_sensor' type='contact'>
        <contact>
          <collision>JK_01/base_link_fixed_joint_lump__JK_01/rear_fender_collision_collision_3</collision>
          <topic>__default_topic__</topic>
        </contact>
        <plugin name='contact_plugin_1' filename='libgazebo_ros_bumper.so'>
          <bumperTopicName>base_collision_1</bumperTopicName>
          <frameName>JK_01/rear_fender_link</frameName>
        </plugin>
        <pose>0 0 0 0 -0 3.14159</pose>
        <alwaysOn>1</alwaysOn>
        <updateRate>10.0</updateRate>
      </sensor>
      <sensor name='JK_01/laser' type='ray'>
        <always_on>1</always_on>
        <update_rate>15</update_rate>
        <visualize>0</visualize>
        <ray>
          <scan>
            <horizontal>
              <samples>811</samples>
              <resolution>1</resolution>
              <min_angle>-2.35619</min_angle>
              <max_angle>2.35619</max_angle>
            </horizontal>
          </scan>
          <range>
            <min>0.05</min>
            <max>25</max>
            <resolution>0.01</resolution>
          </range>
          <noise>
            <type>gaussian</type>
            <mean>0</mean>
            <stddev>0.01</stddev>
          </noise>
        </ray>
        <plugin name='gazebo_ros_laser_controller' filename='libgazebo_ros_laser.so'>
          <gaussianNoise>0.005</gaussianNoise>
          <alwaysOn>1</alwaysOn>
          <updateRate>15.0</updateRate>
          <topicName>scan</topicName>
          <frameName>JK_01/laser_link</frameName>
        </plugin>
        <pose>0.145 0 0.22154 0 -0 0</pose>
      </sensor>
      <gravity>1</gravity>
      <always_on>0</always_on>
      <visualize>0</visualize>
    </link>
    <joint name='JK_01/front_left_wheel' type='revolute'>
      <pose relative_to='JK_01/base_link'>0.131 0.187795 0.0345 0 -0 0</pose>
      <parent>JK_01/base_link</parent>
      <child>JK_01/front_left_wheel_link</child>
      <axis>
        <xyz>0 1 0</xyz>
        <limit>
          <lower>-1e+16</lower>
          <upper>1e+16</upper>
        </limit>
        <dynamics>
          <spring_reference>0</spring_reference>
          <spring_stiffness>0</spring_stiffness>
        </dynamics>
      </axis>
    </joint>
    <link name='JK_01/front_left_wheel_link'>
      <pose relative_to='JK_01/front_left_wheel'>0 0 0 0 -0 0</pose>
      <inertial>
        <pose>0 0 0 0 -0 0</pose>
        <mass>0.477</mass>
        <inertia>
          <ixx>0.0013</ixx>
          <ixy>0</ixy>
          <ixz>0</ixz>
          <iyy>0.0024</iyy>
          <iyz>0</iyz>
          <izz>0.0013</izz>
        </inertia>
      </inertial>
      <collision name='JK_01/front_left_wheel_link_collision'>
        <pose>0 0 0 1.5708 -0 0</pose>
        <geometry>
          <cylinder>
            <length>0.04</length>
            <radius>0.098</radius>
          </cylinder>
        </geometry>
        <surface>
          <contact>
            <ode>
              <kp>1e+07</kp>
              <kd>1</kd>
            </ode>
          </contact>
          <friction>
            <ode>
              <mu>0.75</mu>
              <mu2>0.75</mu2>
              <fdir1>1 0 0</fdir1>
            </ode>
          </friction>
        </surface>
      </collision>
      <visual name='JK_01/front_left_wheel_link_visual'>
        <pose>0 0 0 1.5708 -0 0</pose>
        <geometry>
          <mesh>
            <scale>1 1 1</scale>
            <uri>model://jackal_kinova_gazebo/meshes/jackal-wheel.stl</uri>
          </mesh>
        </geometry>
        <material>
          <script>
            <name>Gazebo/DarkGrey</name>
            <uri>file://media/materials/scripts/gazebo.material</uri>
          </script>
        </material>
      </visual>
      <self_collide>0</self_collide>
    </link>
    <joint name='JK_01/front_right_wheel' type='revolute'>
      <pose relative_to='JK_01/base_link'>0.131 -0.187795 0.0345 0 -0 0</pose>
      <parent>JK_01/base_link</parent>
      <child>JK_01/front_right_wheel_link</child>
      <axis>
        <xyz>0 1 0</xyz>
        <limit>
          <lower>-1e+16</lower>
          <upper>1e+16</upper>
        </limit>
        <dynamics>
          <spring_reference>0</spring_reference>
          <spring_stiffness>0</spring_stiffness>
        </dynamics>
      </axis>
    </joint>
    <link name='JK_01/front_right_wheel_link'>
      <pose relative_to='JK_01/front_right_wheel'>0 0 0 0 -0 0</pose>
      <inertial>
        <pose>0 0 0 0 -0 0</pose>
        <mass>0.477</mass>
        <inertia>
          <ixx>0.0013</ixx>
          <ixy>0</ixy>
          <ixz>0</ixz>
          <iyy>0.0024</iyy>
          <iyz>0</iyz>
          <izz>0.0013</izz>
        </inertia>
      </inertial>
      <collision name='JK_01/front_right_wheel_link_collision'>
        <pose>0 0 0 1.5708 -0 0</pose>
        <geometry>
          <cylinder>
            <length>0.04</length>
            <radius>0.098</radius>
          </cylinder>
        </geometry>
        <surface>
          <contact>
            <ode>
              <kp>1e+07</kp>
              <kd>1</kd>
            </ode>
          </contact>
          <friction>
            <ode>
              <mu>0.75</mu>
              <mu2>0.75</mu2>
              <fdir1>1 0 0</fdir1>
            </ode>
          </friction>
        </surface>
      </collision>
      <visual name='JK_01/front_right_wheel_link_visual'>
        <pose>0 0 0 1.5708 -0 0</pose>
        <geometry>
          <mesh>
            <scale>1 1 1</scale>
            <uri>model://jackal_kinova_gazebo/meshes/jackal-wheel.stl</uri>
          </mesh>
        </geometry>
        <material>
          <script>
            <name>Gazebo/DarkGrey</name>
            <uri>file://media/materials/scripts/gazebo.material</uri>
          </script>
        </material>
      </visual>
      <self_collide>0</self_collide>
    </link>
    <joint name='JK_01/rear_left_wheel' type='revolute'>
      <pose relative_to='JK_01/base_link'>-0.131 0.187795 0.0345 0 -0 0</pose>
      <parent>JK_01/base_link</parent>
      <child>JK_01/rear_left_wheel_link</child>
      <axis>
        <xyz>0 1 0</xyz>
        <limit>
          <lower>-1e+16</lower>
          <upper>1e+16</upper>
        </limit>
        <dynamics>
          <spring_reference>0</spring_reference>
          <spring_stiffness>0</spring_stiffness>
        </dynamics>
      </axis>
    </joint>
    <link name='JK_01/rear_left_wheel_link'>
      <pose relative_to='JK_01/rear_left_wheel'>0 0 0 0 -0 0</pose>
      <inertial>
        <pose>0 0 0 0 -0 0</pose>
        <mass>0.477</mass>
        <inertia>
          <ixx>0.0013</ixx>
          <ixy>0</ixy>
          <ixz>0</ixz>
          <iyy>0.0024</iyy>
          <iyz>0</iyz>
          <izz>0.0013</izz>
        </inertia>
      </inertial>
      <collision name='JK_01/rear_left_wheel_link_collision'>
        <pose>0 0 0 1.5708 -0 0</pose>
        <geometry>
          <cylinder>
            <length>0.04</length>
            <radius>0.098</radius>
          </cylinder>
        </geometry>
        <surface>
          <contact>
            <ode>
              <kp>1e+07</kp>
              <kd>1</kd>
            </ode>
          </contact>
          <friction>
            <ode>
              <mu>0.75</mu>
              <mu2>0.75</mu2>
              <fdir1>1 0 0</fdir1>
            </ode>
          </friction>
        </surface>
      </collision>
      <visual name='JK_01/rear_left_wheel_link_visual'>
        <pose>0 0 0 1.5708 -0 0</pose>
        <geometry>
          <mesh>
            <scale>1 1 1</scale>
            <uri>model://jackal_kinova_gazebo/meshes/jackal-wheel.stl</uri>
          </mesh>
        </geometry>
        <material>
          <script>
            <name>Gazebo/DarkGrey</name>
            <uri>file://media/materials/scripts/gazebo.material</uri>
          </script>
        </material>
      </visual>
      <self_collide>0</self_collide>
    </link>
    <joint name='JK_01/rear_right_wheel' type='revolute'>
      <pose relative_to='JK_01/base_link'>-0.131 -0.187795 0.0345 0 -0 0</pose>
      <parent>JK_01/base_link</parent>
      <child>JK_01/rear_right_wheel_link</child>
      <axis>
        <xyz>0 1 0</xyz>
        <limit>
          <lower>-1e+16</lower>
          <upper>1e+16</upper>
        </limit>
        <dynamics>
          <spring_reference>0</spring_reference>
          <spring_stiffness>0</spring_stiffness>
        </dynamics>
      </axis>
    </joint>
    <link name='JK_01/rear_right_wheel_link'>
      <pose relative_to='JK_01/rear_right_wheel'>0 0 0 0 -0 0</pose>
      <inertial>
        <pose>0 0 0 0 -0 0</pose>
        <mass>0.477</mass>
        <inertia>
          <ixx>0.0013</ixx>
          <ixy>0</ixy>
          <ixz>0</ixz>
          <iyy>0.0024</iyy>
          <iyz>0</iyz>
          <izz>0.0013</izz>
        </inertia>
      </inertial>
      <collision name='JK_01/rear_right_wheel_link_collision'>
        <pose>0 0 0 1.5708 -0 0</pose>
        <geometry>
          <cylinder>
            <length>0.04</length>
            <radius>0.098</radius>
          </cylinder>
        </geometry>
        <surface>
          <contact>
            <ode>
              <kp>1e+07</kp>
              <kd>1</kd>
            </ode>
          </contact>
          <friction>
            <ode>
              <mu>0.75</mu>
              <mu2>0.75</mu2>
              <fdir1>1 0 0</fdir1>
            </ode>
          </friction>
        </surface>
      </collision>
      <visual name='JK_01/rear_right_wheel_link_visual'>
        <pose>0 0 0 1.5708 -0 0</pose>
        <geometry>
          <mesh>
            <scale>1 1 1</scale>
            <uri>model://jackal_kinova_gazebo/meshes/jackal-wheel.stl</uri>
          </mesh>
        </geometry>
        <material>
          <script>
            <name>Gazebo/DarkGrey</name>
            <uri>file://media/materials/scripts/gazebo.material</uri>
          </script>
        </material>
      </visual>
      <self_collide>0</self_collide>
    </link>
    <plugin name='gazebo_ros_control' filename='libgazebo_ros_control.so'>
      <robotNamespace>/JK_01/</robotNamespace>
    </plugin>
    <plugin name='imu_controller' filename='libhector_gazebo_ros_imu.so'>
      <robotNamespace>/JK_01/</robotNamespace>
      <updateRate>50.0</updateRate>
      <frameId>JK_01/base_link</frameId>
      <topicName>imu/data</topicName>
      <accelDrift>0.005 0.005 0.005</accelDrift>
      <accelGaussianNoise>0.005 0.005 0.005</accelGaussianNoise>
      <rateDrift>0.005 0.005 0.005</rateDrift>
      <rateGaussianNoise>0.005 0.005 0.005</rateGaussianNoise>
      <headingDrift>0.005</headingDrift>
      <headingGaussianNoise>0.005</headingGaussianNoise>
      <bodyName>JK_01/base_link</bodyName>
      <xyzOffset>0 0 0</xyzOffset>
      <rpyOffset>0 -0 0</rpyOffset>
      <ignition::corrected_offsets>1</ignition::corrected_offsets>
    </plugin>
    <plugin name='gps_controller' filename='libhector_gazebo_ros_gps.so'>
      <updateRate>40</updateRate>
      <robotNamespace>/JK_01/</robotNamespace>
      <frameId>JK_01/base_link</frameId>
      <topicName>navsat/fix</topicName>
      <velocityTopicName>navsat/vel</velocityTopicName>
      <referenceLatitude>49.9</referenceLatitude>
      <referenceLongitude>8.9</referenceLongitude>
      <referenceHeading>0</referenceHeading>
      <referenceAltitude>0</referenceAltitude>
      <drift>0.0001 0.0001 0.0001</drift>
      <bodyName>JK_01/base_link</bodyName>
      <xyzOffset>-0.18 0.126 0.1815</xyzOffset>
      <rpyOffset>0 -0 0</rpyOffset>
      <ignition::corrected_offsets>1</ignition::corrected_offsets>
    </plugin>
    <static>0</static>
    <plugin name='p3d_base_controller' filename='libgazebo_ros_p3d.so'>
      <robotNamespace>/JK_01/</robotNamespace>
      <alwaysOn>1</alwaysOn>
      <updateRate>50.0</updateRate>
      <bodyName>JK_01/base_link</bodyName>
      <topicName>base_pose_ground_truth</topicName>
      <gaussianNoise>0.01</gaussianNoise>
      <frameName>map</frameName>
      <xyzOffsets>0 0 0</xyzOffsets>
      <rpyOffsets>0 0 0</rpyOffsets>
    </plugin>
  </model>
</sdf>
